[2024-06-02 22:46:42,941: INFO: stage_01_data_ingestion: >>>>>>>> Data Ingestion stage Started <<<<<<<<<<<<]
[2024-06-02 22:46:42,955: INFO: common: yaml file: config\config.yaml loaded successfully]
[2024-06-02 22:46:42,956: INFO: common: yaml file: params.yaml loaded successfully]
[2024-06-02 22:46:42,957: ERROR: stage_01_data_ingestion: yaml file is empty]
Traceback (most recent call last):
  File "c:\users\shaik\documents\programing\ml\rag\src\RAG\utils\common.py", line 32, in read_yaml
    return ConfigBox(content)
           ^^^^^^^^^^^^^^^^^^
  File "C:\Users\shaik\Documents\Programing\TFOD\tfod\Lib\site-packages\box\box.py", line 259, in __init__
    raise BoxValueError("First argument must be mapping or iterable")
box.exceptions.BoxValueError: First argument must be mapping or iterable

During handling of the above exception, another exception occurred:

Traceback (most recent call last):
  File "c:\Users\shaik\Documents\Programing\ML\RAG\src\RAG\pipeline\stage_01_data_ingestion.py", line 23, in <module>
    obj.main()
  File "c:\Users\shaik\Documents\Programing\ML\RAG\src\RAG\pipeline\stage_01_data_ingestion.py", line 12, in main
    config = ConfigurationManager()
             ^^^^^^^^^^^^^^^^^^^^^^
  File "c:\users\shaik\documents\programing\ml\rag\src\RAG\config\configuration.py", line 14, in __init__
    self.params = read_yaml(params_filepath)
                  ^^^^^^^^^^^^^^^^^^^^^^^^^^
  File "C:\Users\shaik\Documents\Programing\TFOD\tfod\Lib\site-packages\ensure\main.py", line 849, in __call__
    return_val = self.f(*args, **kwargs)
                 ^^^^^^^^^^^^^^^^^^^^^^^
  File "c:\users\shaik\documents\programing\ml\rag\src\RAG\utils\common.py", line 34, in read_yaml
    raise ValueError("yaml file is empty")
ValueError: yaml file is empty
[2024-06-02 22:47:26,155: INFO: stage_01_data_ingestion: >>>>>>>> Data Ingestion stage Started <<<<<<<<<<<<]
[2024-06-02 22:47:26,157: INFO: common: yaml file: config\config.yaml loaded successfully]
[2024-06-02 22:47:26,160: INFO: common: yaml file: params.yaml loaded successfully]
[2024-06-02 22:47:26,164: INFO: common: yaml file: schema.yaml loaded successfully]
[2024-06-02 22:47:26,165: ERROR: stage_01_data_ingestion: "'ConfigBox' object has no attribute 'data_ingestion_config'"]
Traceback (most recent call last):
  File "C:\Users\shaik\Documents\Programing\TFOD\tfod\Lib\site-packages\box\box.py", line 503, in __getitem__
    return super().__getitem__(item)
           ^^^^^^^^^^^^^^^^^^^^^^^^^
KeyError: 'data_ingestion_config'

The above exception was the direct cause of the following exception:

Traceback (most recent call last):
  File "C:\Users\shaik\Documents\Programing\TFOD\tfod\Lib\site-packages\box\box.py", line 536, in __getattr__
    value = self.__getitem__(item, _ignore_default=True)
            ^^^^^^^^^^^^^^^^^^^^^^^^^^^^^^^^^^^^^^^^^^^^
  File "C:\Users\shaik\Documents\Programing\TFOD\tfod\Lib\site-packages\box\box.py", line 524, in __getitem__
    raise BoxKeyError(str(err)) from _exception_cause(err)
box.exceptions.BoxKeyError: "'data_ingestion_config'"

During handling of the above exception, another exception occurred:

Traceback (most recent call last):
  File "C:\Users\shaik\Documents\Programing\TFOD\tfod\Lib\site-packages\box\box.py", line 538, in __getattr__
    value = object.__getattribute__(self, item)
            ^^^^^^^^^^^^^^^^^^^^^^^^^^^^^^^^^^^
AttributeError: 'ConfigBox' object has no attribute 'data_ingestion_config'

The above exception was the direct cause of the following exception:

Traceback (most recent call last):
  File "C:\Users\shaik\Documents\Programing\TFOD\tfod\Lib\site-packages\box\config_box.py", line 28, in __getattr__
    return super().__getattr__(item)
           ^^^^^^^^^^^^^^^^^^^^^^^^^
  File "C:\Users\shaik\Documents\Programing\TFOD\tfod\Lib\site-packages\box\box.py", line 552, in __getattr__
    raise BoxKeyError(str(err)) from _exception_cause(err)
box.exceptions.BoxKeyError: "'ConfigBox' object has no attribute 'data_ingestion_config'"

During handling of the above exception, another exception occurred:

Traceback (most recent call last):
  File "C:\Users\shaik\Documents\Programing\TFOD\tfod\Lib\site-packages\box\box.py", line 503, in __getitem__
    return super().__getitem__(item)
           ^^^^^^^^^^^^^^^^^^^^^^^^^
KeyError: 'data_ingestion_config'

The above exception was the direct cause of the following exception:

Traceback (most recent call last):
  File "C:\Users\shaik\Documents\Programing\TFOD\tfod\Lib\site-packages\box\box.py", line 536, in __getattr__
    value = self.__getitem__(item, _ignore_default=True)
            ^^^^^^^^^^^^^^^^^^^^^^^^^^^^^^^^^^^^^^^^^^^^
  File "C:\Users\shaik\Documents\Programing\TFOD\tfod\Lib\site-packages\box\box.py", line 524, in __getitem__
    raise BoxKeyError(str(err)) from _exception_cause(err)
box.exceptions.BoxKeyError: "'data_ingestion_config'"

During handling of the above exception, another exception occurred:

Traceback (most recent call last):
  File "C:\Users\shaik\Documents\Programing\TFOD\tfod\Lib\site-packages\box\box.py", line 538, in __getattr__
    value = object.__getattribute__(self, item)
            ^^^^^^^^^^^^^^^^^^^^^^^^^^^^^^^^^^^
AttributeError: 'ConfigBox' object has no attribute 'data_ingestion_config'

The above exception was the direct cause of the following exception:

Traceback (most recent call last):
  File "c:\Users\shaik\Documents\Programing\ML\RAG\src\RAG\pipeline\stage_01_data_ingestion.py", line 23, in <module>
    obj.main()
  File "c:\Users\shaik\Documents\Programing\ML\RAG\src\RAG\pipeline\stage_01_data_ingestion.py", line 14, in main
    data_ingestion_config = config.get_data_ingestion_config()
                            ^^^^^^^^^^^^^^^^^^^^^^^^^^^^^^^^^^
  File "c:\users\shaik\documents\programing\ml\rag\src\RAG\config\configuration.py", line 18, in get_data_ingestion_config
    config = self.config.data_ingestion_config
             ^^^^^^^^^^^^^^^^^^^^^^^^^^^^^^^^^
  File "C:\Users\shaik\Documents\Programing\TFOD\tfod\Lib\site-packages\box\config_box.py", line 30, in __getattr__
    return super().__getattr__(item.lower())
           ^^^^^^^^^^^^^^^^^^^^^^^^^^^^^^^^^
  File "C:\Users\shaik\Documents\Programing\TFOD\tfod\Lib\site-packages\box\box.py", line 552, in __getattr__
    raise BoxKeyError(str(err)) from _exception_cause(err)
box.exceptions.BoxKeyError: "'ConfigBox' object has no attribute 'data_ingestion_config'"
[2024-06-02 22:48:31,453: INFO: stage_01_data_ingestion: >>>>>>>> Data Ingestion stage Started <<<<<<<<<<<<]
[2024-06-02 22:48:31,473: INFO: common: yaml file: config\config.yaml loaded successfully]
[2024-06-02 22:48:31,475: INFO: common: yaml file: params.yaml loaded successfully]
[2024-06-02 22:48:31,479: INFO: common: yaml file: schema.yaml loaded successfully]
[2024-06-02 22:48:31,482: INFO: common: created directory at: artifacts/data_ingestion]
[2024-06-02 22:48:31,484: ERROR: stage_01_data_ingestion: "'ConfigBox' object has no attribute 'source_uri'"]
Traceback (most recent call last):
  File "C:\Users\shaik\Documents\Programing\TFOD\tfod\Lib\site-packages\box\box.py", line 503, in __getitem__
    return super().__getitem__(item)
           ^^^^^^^^^^^^^^^^^^^^^^^^^
KeyError: 'source_uri'

The above exception was the direct cause of the following exception:

Traceback (most recent call last):
  File "C:\Users\shaik\Documents\Programing\TFOD\tfod\Lib\site-packages\box\box.py", line 536, in __getattr__
    value = self.__getitem__(item, _ignore_default=True)
            ^^^^^^^^^^^^^^^^^^^^^^^^^^^^^^^^^^^^^^^^^^^^
  File "C:\Users\shaik\Documents\Programing\TFOD\tfod\Lib\site-packages\box\box.py", line 524, in __getitem__
    raise BoxKeyError(str(err)) from _exception_cause(err)
box.exceptions.BoxKeyError: "'source_uri'"

During handling of the above exception, another exception occurred:

Traceback (most recent call last):
  File "C:\Users\shaik\Documents\Programing\TFOD\tfod\Lib\site-packages\box\box.py", line 538, in __getattr__
    value = object.__getattribute__(self, item)
            ^^^^^^^^^^^^^^^^^^^^^^^^^^^^^^^^^^^
AttributeError: 'ConfigBox' object has no attribute 'source_uri'

The above exception was the direct cause of the following exception:

Traceback (most recent call last):
  File "C:\Users\shaik\Documents\Programing\TFOD\tfod\Lib\site-packages\box\config_box.py", line 28, in __getattr__
    return super().__getattr__(item)
           ^^^^^^^^^^^^^^^^^^^^^^^^^
  File "C:\Users\shaik\Documents\Programing\TFOD\tfod\Lib\site-packages\box\box.py", line 552, in __getattr__
    raise BoxKeyError(str(err)) from _exception_cause(err)
box.exceptions.BoxKeyError: "'ConfigBox' object has no attribute 'source_uri'"

During handling of the above exception, another exception occurred:

Traceback (most recent call last):
  File "C:\Users\shaik\Documents\Programing\TFOD\tfod\Lib\site-packages\box\box.py", line 503, in __getitem__
    return super().__getitem__(item)
           ^^^^^^^^^^^^^^^^^^^^^^^^^
KeyError: 'source_uri'

The above exception was the direct cause of the following exception:

Traceback (most recent call last):
  File "C:\Users\shaik\Documents\Programing\TFOD\tfod\Lib\site-packages\box\box.py", line 536, in __getattr__
    value = self.__getitem__(item, _ignore_default=True)
            ^^^^^^^^^^^^^^^^^^^^^^^^^^^^^^^^^^^^^^^^^^^^
  File "C:\Users\shaik\Documents\Programing\TFOD\tfod\Lib\site-packages\box\box.py", line 524, in __getitem__
    raise BoxKeyError(str(err)) from _exception_cause(err)
box.exceptions.BoxKeyError: "'source_uri'"

During handling of the above exception, another exception occurred:

Traceback (most recent call last):
  File "C:\Users\shaik\Documents\Programing\TFOD\tfod\Lib\site-packages\box\box.py", line 538, in __getattr__
    value = object.__getattribute__(self, item)
            ^^^^^^^^^^^^^^^^^^^^^^^^^^^^^^^^^^^
AttributeError: 'ConfigBox' object has no attribute 'source_uri'

The above exception was the direct cause of the following exception:

Traceback (most recent call last):
  File "c:\Users\shaik\Documents\Programing\ML\RAG\src\RAG\pipeline\stage_01_data_ingestion.py", line 23, in <module>
    obj.main()
  File "c:\Users\shaik\Documents\Programing\ML\RAG\src\RAG\pipeline\stage_01_data_ingestion.py", line 14, in main
    data_ingestion_config = config.get_data_ingestion_config()
                            ^^^^^^^^^^^^^^^^^^^^^^^^^^^^^^^^^^
  File "c:\users\shaik\documents\programing\ml\rag\src\RAG\config\configuration.py", line 24, in get_data_ingestion_config
    source_uri=config.source_uri,
               ^^^^^^^^^^^^^^^^^
  File "C:\Users\shaik\Documents\Programing\TFOD\tfod\Lib\site-packages\box\config_box.py", line 30, in __getattr__
    return super().__getattr__(item.lower())
           ^^^^^^^^^^^^^^^^^^^^^^^^^^^^^^^^^
  File "C:\Users\shaik\Documents\Programing\TFOD\tfod\Lib\site-packages\box\box.py", line 552, in __getattr__
    raise BoxKeyError(str(err)) from _exception_cause(err)
box.exceptions.BoxKeyError: "'ConfigBox' object has no attribute 'source_uri'"
[2024-06-02 22:49:14,858: INFO: stage_01_data_ingestion: >>>>>>>> Data Ingestion stage Started <<<<<<<<<<<<]
[2024-06-02 22:49:14,872: INFO: common: yaml file: config\config.yaml loaded successfully]
[2024-06-02 22:49:14,875: INFO: common: yaml file: params.yaml loaded successfully]
[2024-06-02 22:49:14,877: INFO: common: yaml file: schema.yaml loaded successfully]
[2024-06-02 22:49:14,878: INFO: common: created directory at: artifacts/data_ingestion]
[2024-06-02 22:49:14,878: INFO: data_ingestion: File Doesn't Exist!>>> let's Download]
[2024-06-02 22:49:14,891: ERROR: stage_01_data_ingestion: No connection adapters were found for 'src/stock_agent/components/stock_names.txthttps://raw.githubusercontent.com/mrdbourke/simple-local-rag/main/human-nutrition-text.pdf']
Traceback (most recent call last):
  File "c:\Users\shaik\Documents\Programing\ML\RAG\src\RAG\pipeline\stage_01_data_ingestion.py", line 23, in <module>
    obj.main()
  File "c:\Users\shaik\Documents\Programing\ML\RAG\src\RAG\pipeline\stage_01_data_ingestion.py", line 16, in main
    data_ingestion.download_data()
  File "c:\users\shaik\documents\programing\ml\rag\src\RAG\components\data_ingestion.py", line 14, in download_data
    response = requests.get(self.config.source_uri)
               ^^^^^^^^^^^^^^^^^^^^^^^^^^^^^^^^^^^^
  File "C:\Users\shaik\Documents\Programing\TFOD\tfod\Lib\site-packages\requests\api.py", line 73, in get
    return request("get", url, params=params, **kwargs)
           ^^^^^^^^^^^^^^^^^^^^^^^^^^^^^^^^^^^^^^^^^^^^
  File "C:\Users\shaik\Documents\Programing\TFOD\tfod\Lib\site-packages\requests\api.py", line 59, in request
    return session.request(method=method, url=url, **kwargs)
           ^^^^^^^^^^^^^^^^^^^^^^^^^^^^^^^^^^^^^^^^^^^^^^^^^
  File "C:\Users\shaik\Documents\Programing\TFOD\tfod\Lib\site-packages\requests\sessions.py", line 589, in request
    resp = self.send(prep, **send_kwargs)
           ^^^^^^^^^^^^^^^^^^^^^^^^^^^^^^
  File "C:\Users\shaik\Documents\Programing\TFOD\tfod\Lib\site-packages\requests\sessions.py", line 697, in send
    adapter = self.get_adapter(url=request.url)
              ^^^^^^^^^^^^^^^^^^^^^^^^^^^^^^^^^
  File "C:\Users\shaik\Documents\Programing\TFOD\tfod\Lib\site-packages\requests\sessions.py", line 794, in get_adapter
    raise InvalidSchema(f"No connection adapters were found for {url!r}")
requests.exceptions.InvalidSchema: No connection adapters were found for 'src/stock_agent/components/stock_names.txthttps://raw.githubusercontent.com/mrdbourke/simple-local-rag/main/human-nutrition-text.pdf'
[2024-06-02 22:50:12,212: INFO: stage_01_data_ingestion: >>>>>>>> Data Ingestion stage Started <<<<<<<<<<<<]
[2024-06-02 22:50:12,231: INFO: common: yaml file: config\config.yaml loaded successfully]
[2024-06-02 22:50:12,232: INFO: common: yaml file: params.yaml loaded successfully]
[2024-06-02 22:50:12,233: INFO: common: yaml file: schema.yaml loaded successfully]
[2024-06-02 22:50:12,234: INFO: common: created directory at: artifacts/data_ingestion]
[2024-06-02 22:50:12,235: INFO: data_ingestion: File Doesn't Exist!>>> let's Download]
[2024-06-02 22:51:10,205: INFO: data_ingestion: >>>>>> Downloaded to artifacts/data_ingestion/human-nutrition-text.]
[2024-06-02 22:51:10,215: INFO: stage_01_data_ingestion: >>>>>>>> Data Ingestion stage Completed <<<<<<<<<<]
[2024-06-02 22:54:31,526: INFO: stage_01_data_ingestion: >>>>>>>> Data Ingestion stage Started <<<<<<<<<<<<]
[2024-06-02 22:54:31,543: INFO: common: yaml file: config\config.yaml loaded successfully]
[2024-06-02 22:54:31,546: INFO: common: yaml file: params.yaml loaded successfully]
[2024-06-02 22:54:31,548: INFO: common: yaml file: schema.yaml loaded successfully]
[2024-06-02 22:54:31,550: INFO: common: created directory at: artifacts/data_ingestion]
[2024-06-02 22:54:31,551: INFO: data_ingestion: File Already Exist!]
[2024-06-02 22:54:31,553: INFO: stage_01_data_ingestion: >>>>>>>> Data Ingestion stage Completed <<<<<<<<<<]
[2024-06-03 00:25:58,189: INFO: stage_01_data_ingestion: >>>>>>>> Data Ingestion stage Started <<<<<<<<<<<<]
[2024-06-03 00:25:58,200: INFO: common: yaml file: config\config.yaml loaded successfully]
[2024-06-03 00:25:58,207: INFO: common: yaml file: params.yaml loaded successfully]
[2024-06-03 00:25:58,210: INFO: common: yaml file: schema.yaml loaded successfully]
[2024-06-03 00:25:58,211: INFO: common: created directory at: artifacts/data_ingestion]
[2024-06-03 00:25:58,212: INFO: data_ingestion: File Already Exist!]
[2024-06-03 00:26:05,783: INFO: stage_01_data_ingestion: >>>>>>>> Data Ingestion stage Completed <<<<<<<<<<]
[2024-06-03 00:28:20,775: INFO: stage_01_data_ingestion: >>>>>>>> Data Ingestion stage Started <<<<<<<<<<<<]
[2024-06-03 00:28:20,778: INFO: common: yaml file: config\config.yaml loaded successfully]
[2024-06-03 00:28:20,779: INFO: common: yaml file: params.yaml loaded successfully]
[2024-06-03 00:28:20,780: INFO: common: yaml file: schema.yaml loaded successfully]
[2024-06-03 00:28:20,781: INFO: common: created directory at: artifacts/data_ingestion]
[2024-06-03 00:28:20,782: INFO: data_ingestion: File Already Exist!]
[2024-06-03 00:28:28,206: INFO: stage_01_data_ingestion: >>>>>>>> Data Ingestion stage Completed <<<<<<<<<<]
[2024-06-03 00:28:41,349: INFO: stage_01_data_ingestion: >>>>>>>> Data Ingestion stage Started <<<<<<<<<<<<]
[2024-06-03 00:28:41,351: INFO: common: yaml file: config\config.yaml loaded successfully]
[2024-06-03 00:28:41,352: INFO: common: yaml file: params.yaml loaded successfully]
[2024-06-03 00:28:41,353: INFO: common: yaml file: schema.yaml loaded successfully]
[2024-06-03 00:28:41,354: INFO: common: created directory at: artifacts/data_ingestion]
[2024-06-03 00:28:41,355: INFO: data_ingestion: File Already Exist!]
[2024-06-03 00:28:48,527: INFO: stage_01_data_ingestion: >>>>>>>> Data Ingestion stage Completed <<<<<<<<<<]
[2024-06-03 00:29:08,547: INFO: stage_01_data_ingestion: >>>>>>>> Data Ingestion stage Started <<<<<<<<<<<<]
[2024-06-03 00:29:08,552: INFO: common: yaml file: config\config.yaml loaded successfully]
[2024-06-03 00:29:08,554: INFO: common: yaml file: params.yaml loaded successfully]
[2024-06-03 00:29:08,556: INFO: common: yaml file: schema.yaml loaded successfully]
[2024-06-03 00:29:08,558: INFO: common: created directory at: artifacts/data_ingestion]
[2024-06-03 00:29:08,558: INFO: data_ingestion: File Already Exist!]
[2024-06-03 00:29:18,295: INFO: stage_01_data_ingestion: >>>>>>>> Data Ingestion stage Completed <<<<<<<<<<]
[2024-06-03 00:44:44,909: INFO: stage_01_data_ingestion: >>>>>>>> Data Ingestion stage Started <<<<<<<<<<<<]
[2024-06-03 00:44:44,911: INFO: common: yaml file: config\config.yaml loaded successfully]
[2024-06-03 00:44:44,912: INFO: common: yaml file: params.yaml loaded successfully]
[2024-06-03 00:44:44,913: INFO: common: yaml file: schema.yaml loaded successfully]
[2024-06-03 00:44:44,915: INFO: common: created directory at: artifacts/data_ingestion]
[2024-06-03 00:44:44,915: INFO: data_ingestion: File Already Exist!]
[2024-06-03 00:44:52,867: INFO: stage_01_data_ingestion: >>>>>>>> Data Ingestion stage Completed <<<<<<<<<<]
[2024-06-03 09:13:08,114: INFO: stage_01_data_ingestion: >>>>>>>> Data Ingestion stage Started <<<<<<<<<<<<]
[2024-06-03 09:13:08,127: INFO: common: yaml file: config\config.yaml loaded successfully]
[2024-06-03 09:13:08,141: INFO: common: yaml file: params.yaml loaded successfully]
[2024-06-03 09:13:08,145: INFO: common: yaml file: schema.yaml loaded successfully]
[2024-06-03 09:13:08,146: INFO: common: created directory at: artifacts/data_ingestion]
[2024-06-03 09:13:08,147: INFO: data_ingestion: File Already Exist!]
[2024-06-03 09:13:15,441: INFO: stage_01_data_ingestion: >>>>>>>> Data Ingestion stage Completed <<<<<<<<<<]
[2024-06-03 12:06:49,840: INFO: stage_01_data_ingestion: >>>>>>>> Data Ingestion stage Started <<<<<<<<<<<<]
[2024-06-03 12:06:49,852: INFO: common: yaml file: config\config.yaml loaded successfully]
[2024-06-03 12:06:49,854: INFO: common: yaml file: params.yaml loaded successfully]
[2024-06-03 12:06:49,858: INFO: common: yaml file: schema.yaml loaded successfully]
[2024-06-03 12:06:49,858: INFO: common: created directory at: artifacts/data_ingestion]
[2024-06-03 12:06:49,859: INFO: SentenceTransformer: Load pretrained SentenceTransformer: all-mpnet-base-v2]
[2024-06-03 12:10:18,133: INFO: data_ingestion: File Already Exist!]
[2024-06-03 12:10:25,598: ERROR: stage_01_data_ingestion: invalid group reference 1 at position 3]
Traceback (most recent call last):
  File "c:\Users\shaik\Documents\Programing\ML\RAG\src\RAG\pipeline\stage_01_data_ingestion.py", line 29, in <module>
    pages_and_text = obj.main()
                     ^^^^^^^^^^
  File "c:\Users\shaik\Documents\Programing\ML\RAG\src\RAG\pipeline\stage_01_data_ingestion.py", line 20, in main
    pages_and_chunks = data_ingestion.split_chunks(pages_and_text)
                       ^^^^^^^^^^^^^^^^^^^^^^^^^^^^^^^^^^^^^^^^^^^
  File "c:\users\shaik\documents\programing\ml\rag\src\RAG\components\data_ingestion.py", line 84, in split_chunks
    joined_chunk = re.sub(r'\.[A-Z]',r'. \1', joined_chunk)
                   ^^^^^^^^^^^^^^^^^^^^^^^^^^^^^^^^^^^^^^^^
  File "C:\Users\shaik\AppData\Local\Programs\Python\Python311\Lib\re\__init__.py", line 185, in sub
    return _compile(pattern, flags).sub(repl, string, count)
           ^^^^^^^^^^^^^^^^^^^^^^^^^^^^^^^^^^^^^^^^^^^^^^^^^
  File "C:\Users\shaik\AppData\Local\Programs\Python\Python311\Lib\re\__init__.py", line 317, in _subx
    template = _compile_repl(template, pattern)
               ^^^^^^^^^^^^^^^^^^^^^^^^^^^^^^^^
  File "C:\Users\shaik\AppData\Local\Programs\Python\Python311\Lib\re\__init__.py", line 308, in _compile_repl
    return _parser.parse_template(repl, pattern)
           ^^^^^^^^^^^^^^^^^^^^^^^^^^^^^^^^^^^^^
  File "C:\Users\shaik\AppData\Local\Programs\Python\Python311\Lib\re\_parser.py", line 1072, in parse_template
    addgroup(int(this[1:]), len(this) - 1)
  File "C:\Users\shaik\AppData\Local\Programs\Python\Python311\Lib\re\_parser.py", line 1008, in addgroup
    raise s.error("invalid group reference %d" % index, pos)
re.error: invalid group reference 1 at position 3
[2024-06-03 12:18:23,907: INFO: stage_01_data_ingestion: >>>>>>>> Data Ingestion stage Started <<<<<<<<<<<<]
[2024-06-03 12:18:23,910: INFO: common: yaml file: config\config.yaml loaded successfully]
[2024-06-03 12:18:23,911: INFO: common: yaml file: params.yaml loaded successfully]
[2024-06-03 12:18:23,912: INFO: common: yaml file: schema.yaml loaded successfully]
[2024-06-03 12:18:23,914: INFO: common: created directory at: artifacts/data_ingestion]
[2024-06-03 12:18:23,914: INFO: SentenceTransformer: Load pretrained SentenceTransformer: all-mpnet-base-v2]
[2024-06-03 12:18:28,676: INFO: data_ingestion: File Already Exist!]
[2024-06-03 12:18:36,255: INFO: stage_01_data_ingestion: >>>>>>>> Data Ingestion stage Completed <<<<<<<<<<]
[2024-06-03 13:07:41,238: INFO: stage_01_data_ingestion: >>>>>>>> Data Ingestion stage Started <<<<<<<<<<<<]
[2024-06-03 13:07:41,251: INFO: common: yaml file: config\config.yaml loaded successfully]
[2024-06-03 13:07:41,253: INFO: common: yaml file: params.yaml loaded successfully]
[2024-06-03 13:07:41,255: INFO: common: yaml file: schema.yaml loaded successfully]
[2024-06-03 13:07:41,256: INFO: common: created directory at: artifacts/data_ingestion]
[2024-06-03 13:07:41,257: INFO: SentenceTransformer: Load pretrained SentenceTransformer: all-mpnet-base-v2]
[2024-06-03 13:07:50,210: ERROR: stage_01_data_ingestion: 'PINECONE_API_KEY']
Traceback (most recent call last):
  File "c:\Users\shaik\Documents\Programing\ML\RAG\src\RAG\pipeline\stage_01_data_ingestion.py", line 29, in <module>
    pages_and_text = obj.main()
                     ^^^^^^^^^^
  File "c:\Users\shaik\Documents\Programing\ML\RAG\src\RAG\pipeline\stage_01_data_ingestion.py", line 16, in main
    data_ingestion = DataIngestion(data_ingestion_config)
                     ^^^^^^^^^^^^^^^^^^^^^^^^^^^^^^^^^^^^
  File "c:\users\shaik\documents\programing\ml\rag\src\RAG\components\data_ingestion.py", line 24, in __init__
    self.pc = Pinecone(api_key=os.environ["PINECONE_API_KEY"])
                               ~~~~~~~~~~^^^^^^^^^^^^^^^^^^^^
  File "<frozen os>", line 679, in __getitem__
KeyError: 'PINECONE_API_KEY'
[2024-06-03 13:09:16,823: INFO: stage_01_data_ingestion: >>>>>>>> Data Ingestion stage Started <<<<<<<<<<<<]
[2024-06-03 13:09:16,825: INFO: common: yaml file: config\config.yaml loaded successfully]
[2024-06-03 13:09:16,827: INFO: common: yaml file: params.yaml loaded successfully]
[2024-06-03 13:09:16,828: INFO: common: yaml file: schema.yaml loaded successfully]
[2024-06-03 13:09:16,833: INFO: common: created directory at: artifacts/data_ingestion]
[2024-06-03 13:09:16,834: INFO: SentenceTransformer: Load pretrained SentenceTransformer: all-mpnet-base-v2]
[2024-06-03 13:09:21,905: INFO: data_ingestion: File Already Exist!]
[2024-06-03 13:09:22,984: INFO: data_ingestion: >>>>>>>> Embedding Started <<<<<<<<<]
[2024-06-03 13:09:22,984: ERROR: stage_01_data_ingestion: 'function' object has no attribute 'DataFrame']
Traceback (most recent call last):
  File "c:\Users\shaik\Documents\Programing\ML\RAG\src\RAG\pipeline\stage_01_data_ingestion.py", line 30, in <module>
    pages_and_text = obj.main()
                     ^^^^^^^^^^
  File "c:\Users\shaik\Documents\Programing\ML\RAG\src\RAG\pipeline\stage_01_data_ingestion.py", line 22, in main
    pages_and_chunks_over_min_token_len = data_ingestion.embed_chunks(pages_and_chunks)
                                          ^^^^^^^^^^^^^^^^^^^^^^^^^^^^^^^^^^^^^^^^^^^^^
  File "c:\users\shaik\documents\programing\ml\rag\src\RAG\components\data_ingestion.py", line 106, in embed_chunks
    df = pd.DataFrame(pages_and_chunks)
         ^^^^^^^^^^^^
AttributeError: 'function' object has no attribute 'DataFrame'
[2024-06-03 13:11:19,647: INFO: stage_01_data_ingestion: >>>>>>>> Data Ingestion stage Started <<<<<<<<<<<<]
[2024-06-03 13:11:19,650: INFO: common: yaml file: config\config.yaml loaded successfully]
[2024-06-03 13:11:19,651: INFO: common: yaml file: params.yaml loaded successfully]
[2024-06-03 13:11:19,652: INFO: common: yaml file: schema.yaml loaded successfully]
[2024-06-03 13:11:19,654: INFO: common: created directory at: artifacts/data_ingestion]
[2024-06-03 13:11:19,654: INFO: SentenceTransformer: Load pretrained SentenceTransformer: all-mpnet-base-v2]
[2024-06-03 13:11:25,409: INFO: data_ingestion: File Already Exist!]
[2024-06-03 13:11:26,606: INFO: data_ingestion: >>>>>>>> Embedding Started <<<<<<<<<]
[2024-06-03 13:11:26,714: ERROR: stage_01_data_ingestion: Invalid comparison between dtype=int64 and str]
Traceback (most recent call last):
  File "c:\Users\shaik\Documents\Programing\ML\RAG\src\RAG\pipeline\stage_01_data_ingestion.py", line 30, in <module>
    pages_and_text = obj.main()
                     ^^^^^^^^^^
  File "c:\Users\shaik\Documents\Programing\ML\RAG\src\RAG\pipeline\stage_01_data_ingestion.py", line 22, in main
    pages_and_chunks_over_min_token_len = data_ingestion.embed_chunks(pages_and_chunks)
                                          ^^^^^^^^^^^^^^^^^^^^^^^^^^^^^^^^^^^^^^^^^^^^^
  File "c:\users\shaik\documents\programing\ml\rag\src\RAG\components\data_ingestion.py", line 107, in embed_chunks
    pages_and_chunks_over_min_token_len = df[df["chunk_token_count"] > self.config.min_token_length].to_dict(orient="records")
                                             ^^^^^^^^^^^^^^^^^^^^^^^^^^^^^^^^^^^^^^^^^^^^^^^^^^^^^^
  File "C:\Users\shaik\Documents\Programing\TFOD\tfod\Lib\site-packages\pandas\core\ops\common.py", line 81, in new_method
    return method(self, other)
           ^^^^^^^^^^^^^^^^^^^
  File "C:\Users\shaik\Documents\Programing\TFOD\tfod\Lib\site-packages\pandas\core\arraylike.py", line 56, in __gt__
    return self._cmp_method(other, operator.gt)
           ^^^^^^^^^^^^^^^^^^^^^^^^^^^^^^^^^^^^
  File "C:\Users\shaik\Documents\Programing\TFOD\tfod\Lib\site-packages\pandas\core\series.py", line 6096, in _cmp_method
    res_values = ops.comparison_op(lvalues, rvalues, op)
                 ^^^^^^^^^^^^^^^^^^^^^^^^^^^^^^^^^^^^^^^
  File "C:\Users\shaik\Documents\Programing\TFOD\tfod\Lib\site-packages\pandas\core\ops\array_ops.py", line 290, in comparison_op
    return invalid_comparison(lvalues, rvalues, op)
           ^^^^^^^^^^^^^^^^^^^^^^^^^^^^^^^^^^^^^^^^
  File "C:\Users\shaik\Documents\Programing\TFOD\tfod\Lib\site-packages\pandas\core\ops\invalid.py", line 36, in invalid_comparison
    raise TypeError(f"Invalid comparison between dtype={left.dtype} and {typ}")
TypeError: Invalid comparison between dtype=int64 and str
[2024-06-03 13:15:18,665: INFO: stage_01_data_ingestion: >>>>>>>> Data Ingestion stage Started <<<<<<<<<<<<]
[2024-06-03 13:15:18,667: INFO: common: yaml file: config\config.yaml loaded successfully]
[2024-06-03 13:15:18,669: INFO: common: yaml file: params.yaml loaded successfully]
[2024-06-03 13:15:18,670: INFO: common: yaml file: schema.yaml loaded successfully]
[2024-06-03 13:15:18,673: INFO: common: created directory at: artifacts/data_ingestion]
[2024-06-03 13:15:18,674: INFO: SentenceTransformer: Load pretrained SentenceTransformer: all-mpnet-base-v2]
[2024-06-03 13:15:23,100: INFO: data_ingestion: File Already Exist!]
[2024-06-03 13:15:24,425: INFO: data_ingestion: >>>>>>>> Embedding Started <<<<<<<<<]
[2024-06-03 13:15:24,432: ERROR: stage_01_data_ingestion: Invalid comparison between dtype=int64 and str]
Traceback (most recent call last):
  File "c:\Users\shaik\Documents\Programing\ML\RAG\src\RAG\pipeline\stage_01_data_ingestion.py", line 30, in <module>
    pages_and_text = obj.main()
                     ^^^^^^^^^^
  File "c:\Users\shaik\Documents\Programing\ML\RAG\src\RAG\pipeline\stage_01_data_ingestion.py", line 22, in main
    pages_and_chunks_over_min_token_len = data_ingestion.embed_chunks(pages_and_chunks)
                                          ^^^^^^^^^^^^^^^^^^^^^^^^^^^^^^^^^^^^^^^^^^^^^
  File "c:\users\shaik\documents\programing\ml\rag\src\RAG\components\data_ingestion.py", line 107, in embed_chunks
    pages_and_chunks_over_min_token_len = df[df["chunk_token_count"] > self.config.min_token_length].to_dict(orient="records")
                                             ^^^^^^^^^^^^^^^^^^^^^^^^^^^^^^^^^^^^^^^^^^^^^^^^^^^^^^
  File "C:\Users\shaik\Documents\Programing\TFOD\tfod\Lib\site-packages\pandas\core\ops\common.py", line 81, in new_method
    return method(self, other)
           ^^^^^^^^^^^^^^^^^^^
  File "C:\Users\shaik\Documents\Programing\TFOD\tfod\Lib\site-packages\pandas\core\arraylike.py", line 56, in __gt__
    return self._cmp_method(other, operator.gt)
           ^^^^^^^^^^^^^^^^^^^^^^^^^^^^^^^^^^^^
  File "C:\Users\shaik\Documents\Programing\TFOD\tfod\Lib\site-packages\pandas\core\series.py", line 6096, in _cmp_method
    res_values = ops.comparison_op(lvalues, rvalues, op)
                 ^^^^^^^^^^^^^^^^^^^^^^^^^^^^^^^^^^^^^^^
  File "C:\Users\shaik\Documents\Programing\TFOD\tfod\Lib\site-packages\pandas\core\ops\array_ops.py", line 290, in comparison_op
    return invalid_comparison(lvalues, rvalues, op)
           ^^^^^^^^^^^^^^^^^^^^^^^^^^^^^^^^^^^^^^^^
  File "C:\Users\shaik\Documents\Programing\TFOD\tfod\Lib\site-packages\pandas\core\ops\invalid.py", line 36, in invalid_comparison
    raise TypeError(f"Invalid comparison between dtype={left.dtype} and {typ}")
TypeError: Invalid comparison between dtype=int64 and str
[2024-06-03 13:18:35,960: INFO: stage_01_data_ingestion: >>>>>>>> Data Ingestion stage Started <<<<<<<<<<<<]
[2024-06-03 13:18:35,964: INFO: common: yaml file: config\config.yaml loaded successfully]
[2024-06-03 13:18:35,966: INFO: common: yaml file: params.yaml loaded successfully]
[2024-06-03 13:18:35,968: INFO: common: yaml file: schema.yaml loaded successfully]
[2024-06-03 13:18:35,971: INFO: common: created directory at: artifacts/data_ingestion]
[2024-06-03 13:18:35,972: INFO: SentenceTransformer: Load pretrained SentenceTransformer: all-mpnet-base-v2]
[2024-06-03 13:18:40,682: INFO: data_ingestion: File Already Exist!]
[2024-06-03 13:18:41,449: INFO: data_ingestion: >>>>>>>> Embedding Started <<<<<<<<<]
[2024-06-03 13:18:41,452: ERROR: stage_01_data_ingestion: invalid literal for int() with base 10: '30,']
Traceback (most recent call last):
  File "c:\Users\shaik\Documents\Programing\ML\RAG\src\RAG\pipeline\stage_01_data_ingestion.py", line 30, in <module>
    pages_and_text = obj.main()
                     ^^^^^^^^^^
  File "c:\Users\shaik\Documents\Programing\ML\RAG\src\RAG\pipeline\stage_01_data_ingestion.py", line 22, in main
    pages_and_chunks_over_min_token_len = data_ingestion.embed_chunks(pages_and_chunks)
                                          ^^^^^^^^^^^^^^^^^^^^^^^^^^^^^^^^^^^^^^^^^^^^^
  File "c:\users\shaik\documents\programing\ml\rag\src\RAG\components\data_ingestion.py", line 107, in embed_chunks
    pages_and_chunks_over_min_token_len = df[df["chunk_token_count"] > int(self.config.min_token_length)].to_dict(orient="records")
                                                                       ^^^^^^^^^^^^^^^^^^^^^^^^^^^^^^^^^
ValueError: invalid literal for int() with base 10: '30,'
[2024-06-03 13:20:22,318: INFO: stage_01_data_ingestion: >>>>>>>> Data Ingestion stage Started <<<<<<<<<<<<]
[2024-06-03 13:20:22,333: INFO: common: yaml file: config\config.yaml loaded successfully]
[2024-06-03 13:20:22,335: INFO: common: yaml file: params.yaml loaded successfully]
[2024-06-03 13:20:22,337: INFO: common: yaml file: schema.yaml loaded successfully]
[2024-06-03 13:20:22,339: INFO: common: created directory at: artifacts/data_ingestion]
[2024-06-03 13:20:22,340: INFO: SentenceTransformer: Load pretrained SentenceTransformer: all-mpnet-base-v2]
[2024-06-03 13:20:27,197: INFO: data_ingestion: File Already Exist!]
[2024-06-03 13:20:28,090: INFO: data_ingestion: >>>>>>>> Embedding Started <<<<<<<<<]
[2024-06-03 13:20:28,105: ERROR: stage_01_data_ingestion: 'list' object has no attribute 'to_dict']
Traceback (most recent call last):
  File "c:\Users\shaik\Documents\Programing\ML\RAG\src\RAG\pipeline\stage_01_data_ingestion.py", line 30, in <module>
    pages_and_text = obj.main()
                     ^^^^^^^^^^
  File "c:\Users\shaik\Documents\Programing\ML\RAG\src\RAG\pipeline\stage_01_data_ingestion.py", line 22, in main
    pages_and_chunks_over_min_token_len = data_ingestion.embed_chunks(pages_and_chunks)
                                          ^^^^^^^^^^^^^^^^^^^^^^^^^^^^^^^^^^^^^^^^^^^^^
  File "c:\users\shaik\documents\programing\ml\rag\src\RAG\components\data_ingestion.py", line 118, in embed_chunks
    return pages_and_chunks_over_min_token_len.to_dict(orient="records")
           ^^^^^^^^^^^^^^^^^^^^^^^^^^^^^^^^^^^^^^^^^^^
AttributeError: 'list' object has no attribute 'to_dict'
[2024-06-03 13:24:39,191: INFO: stage_01_data_ingestion: >>>>>>>> Data Ingestion stage Started <<<<<<<<<<<<]
[2024-06-03 13:24:39,193: INFO: common: yaml file: config\config.yaml loaded successfully]
[2024-06-03 13:24:39,194: INFO: common: yaml file: params.yaml loaded successfully]
[2024-06-03 13:24:39,194: INFO: common: yaml file: schema.yaml loaded successfully]
[2024-06-03 13:24:39,196: INFO: common: created directory at: artifacts/data_ingestion]
[2024-06-03 13:24:39,196: INFO: SentenceTransformer: Load pretrained SentenceTransformer: all-mpnet-base-v2]
[2024-06-03 13:24:43,723: INFO: data_ingestion: File Already Exist!]
[2024-06-03 13:24:44,634: INFO: data_ingestion: >>>>>>>> Embedding Started <<<<<<<<<]
[2024-06-03 13:24:44,640: ERROR: stage_01_data_ingestion: Sequential.forward() got an unexpected keyword argument 'batch_size']
Traceback (most recent call last):
  File "c:\Users\shaik\Documents\Programing\ML\RAG\src\RAG\pipeline\stage_01_data_ingestion.py", line 30, in <module>
    pages_and_text = obj.main()
                     ^^^^^^^^^^
  File "c:\Users\shaik\Documents\Programing\ML\RAG\src\RAG\pipeline\stage_01_data_ingestion.py", line 22, in main
    pages_and_chunks_over_min_token_len = data_ingestion.embed_chunks(pages_and_chunks)
                                          ^^^^^^^^^^^^^^^^^^^^^^^^^^^^^^^^^^^^^^^^^^^^^
  File "c:\users\shaik\documents\programing\ml\rag\src\RAG\components\data_ingestion.py", line 109, in embed_chunks
    text_chunks_embeddings = self.embedding_model(
                             ^^^^^^^^^^^^^^^^^^^^^
  File "C:\Users\shaik\Documents\Programing\TFOD\tfod\Lib\site-packages\torch\nn\modules\module.py", line 1532, in _wrapped_call_impl
    return self._call_impl(*args, **kwargs)
           ^^^^^^^^^^^^^^^^^^^^^^^^^^^^^^^^
  File "C:\Users\shaik\Documents\Programing\TFOD\tfod\Lib\site-packages\torch\nn\modules\module.py", line 1541, in _call_impl
    return forward_call(*args, **kwargs)
           ^^^^^^^^^^^^^^^^^^^^^^^^^^^^^
TypeError: Sequential.forward() got an unexpected keyword argument 'batch_size'
[2024-06-03 13:25:12,605: INFO: stage_01_data_ingestion: >>>>>>>> Data Ingestion stage Started <<<<<<<<<<<<]
[2024-06-03 13:25:12,610: INFO: common: yaml file: config\config.yaml loaded successfully]
[2024-06-03 13:25:12,612: INFO: common: yaml file: params.yaml loaded successfully]
[2024-06-03 13:25:12,614: INFO: common: yaml file: schema.yaml loaded successfully]
[2024-06-03 13:25:12,619: INFO: common: created directory at: artifacts/data_ingestion]
[2024-06-03 13:25:12,619: INFO: SentenceTransformer: Load pretrained SentenceTransformer: all-mpnet-base-v2]
[2024-06-03 13:25:18,267: INFO: data_ingestion: File Already Exist!]
[2024-06-03 13:25:19,048: INFO: data_ingestion: >>>>>>>> Embedding Started <<<<<<<<<]
[2024-06-03 13:26:08,769: INFO: data_ingestion: >>>>>>>> Embedding Completed <<<<<<<<<]
[2024-06-03 13:26:08,926: INFO: stage_01_data_ingestion: >>>>>>>> Data Ingestion stage Completed <<<<<<<<<<]
[2024-06-03 14:56:30,171: INFO: stage_01_data_ingestion: >>>>>>>> Data Ingestion stage Started <<<<<<<<<<<<]
[2024-06-03 14:56:30,176: INFO: common: yaml file: config\config.yaml loaded successfully]
[2024-06-03 14:56:30,178: INFO: common: yaml file: params.yaml loaded successfully]
[2024-06-03 14:56:30,179: INFO: common: yaml file: schema.yaml loaded successfully]
[2024-06-03 14:56:30,182: INFO: common: created directory at: artifacts/data_ingestion]
[2024-06-03 14:56:30,183: INFO: SentenceTransformer: Load pretrained SentenceTransformer: all-mpnet-base-v2]
[2024-06-03 14:56:41,623: INFO: data_ingestion: File Already Exist!]
[2024-06-03 14:56:44,227: INFO: data_ingestion: >>>>>>>> Embedding Started <<<<<<<<<]
[2024-06-03 14:57:51,557: INFO: data_ingestion: >>>>>>>> Embedding Completed <<<<<<<<<]
[2024-06-03 14:57:51,724: INFO: stage_01_data_ingestion: >>>>>>>> Data Ingestion stage Completed <<<<<<<<<<]
[2024-06-03 15:01:31,880: INFO: stage_01_data_ingestion: >>>>>>>> Data Ingestion stage Started <<<<<<<<<<<<]
[2024-06-03 15:01:31,888: INFO: common: yaml file: config\config.yaml loaded successfully]
[2024-06-03 15:01:31,894: INFO: common: yaml file: params.yaml loaded successfully]
[2024-06-03 15:01:31,901: INFO: common: yaml file: schema.yaml loaded successfully]
[2024-06-03 15:01:31,932: INFO: common: created directory at: artifacts/data_ingestion]
[2024-06-03 15:01:31,947: INFO: SentenceTransformer: Load pretrained SentenceTransformer: all-mpnet-base-v2]
[2024-06-03 15:01:37,791: INFO: data_ingestion: File Already Exist!]
[2024-06-03 15:01:39,074: INFO: data_ingestion: >>>>>>>> Embedding Started <<<<<<<<<]
[2024-06-03 15:02:31,020: INFO: data_ingestion: >>>>>>>> Embedding Completed <<<<<<<<<]
[2024-06-03 15:02:42,273: INFO: stage_01_data_ingestion: >>>>>>>> Data Ingestion stage Completed <<<<<<<<<<]
[2024-06-03 15:09:09,377: INFO: stage_01_data_ingestion: >>>>>>>> Data Ingestion stage Started <<<<<<<<<<<<]
[2024-06-03 15:09:09,379: INFO: common: yaml file: config\config.yaml loaded successfully]
[2024-06-03 15:09:09,381: INFO: common: yaml file: params.yaml loaded successfully]
[2024-06-03 15:09:09,383: INFO: common: yaml file: schema.yaml loaded successfully]
[2024-06-03 15:09:09,387: INFO: common: created directory at: artifacts/data_ingestion]
[2024-06-03 15:09:09,388: INFO: SentenceTransformer: Load pretrained SentenceTransformer: all-mpnet-base-v2]
[2024-06-03 15:09:15,975: INFO: data_ingestion: File Already Exist!]
[2024-06-03 15:09:17,207: INFO: data_ingestion: >>>>>>>> Embedding Started <<<<<<<<<]
[2024-06-03 15:10:20,220: INFO: data_ingestion: >>>>>>>> Embedding Completed <<<<<<<<<]
[2024-06-03 15:10:21,059: WARNING: data_ingestion: Index Already Exist! Deleting Index:rag-index]
[2024-06-03 15:10:39,177: INFO: data_ingestion: Data is Going To Load to Pinecone!]
[2024-06-03 15:10:43,997: INFO: data_ingestion: Vectors Loaded to Pinecone]
[2024-06-03 15:10:44,063: INFO: stage_01_data_ingestion: >>>>>>>> Data Ingestion stage Completed <<<<<<<<<<]
[2024-06-03 15:12:03,012: INFO: stage_01_data_ingestion: >>>>>>>> Data Ingestion stage Started <<<<<<<<<<<<]
[2024-06-03 15:12:03,022: INFO: common: yaml file: config\config.yaml loaded successfully]
[2024-06-03 15:12:03,024: INFO: common: yaml file: params.yaml loaded successfully]
[2024-06-03 15:12:03,025: INFO: common: yaml file: schema.yaml loaded successfully]
[2024-06-03 15:12:03,028: INFO: common: created directory at: artifacts/data_ingestion]
[2024-06-03 15:12:03,029: INFO: SentenceTransformer: Load pretrained SentenceTransformer: all-mpnet-base-v2]
[2024-06-03 15:12:07,990: INFO: data_ingestion: File Already Exist!]
[2024-06-03 15:12:15,501: INFO: data_ingestion: >>>>>>>> Embedding Started <<<<<<<<<]
[2024-06-03 15:41:49,374: INFO: data_ingestion: >>>>>>>> Embedding Completed <<<<<<<<<]
[2024-06-03 15:41:50,526: WARNING: data_ingestion: Index Already Exist! Deleting Index:rag-index]
[2024-06-03 15:42:02,795: INFO: data_ingestion: Data is Going To Load to Pinecone!]
[2024-06-03 15:42:51,610: ERROR: stage_01_data_ingestion: (400)
Reason: Bad Request
HTTP response headers: HTTPHeaderDict({'Date': 'Mon, 03 Jun 2024 10:12:51 GMT', 'Content-Type': 'application/json', 'Content-Length': '118', 'Connection': 'keep-alive', 'x-pinecone-request-latency-ms': '39446', 'x-pinecone-request-id': '6976461903471582505', 'x-envoy-upstream-service-time': '0', 'server': 'envoy'})
HTTP response body: {"code":11,"message":"Error, message length too large: found 6452785 bytes, the limit is: 4194304 bytes","details":[]}
]
Traceback (most recent call last):
  File "c:\Users\shaik\Documents\Programing\ML\RAG\src\RAG\pipeline\stage_01_data_ingestion.py", line 31, in <module>
    pages_and_text = obj.main()
                     ^^^^^^^^^^
  File "c:\Users\shaik\Documents\Programing\ML\RAG\src\RAG\pipeline\stage_01_data_ingestion.py", line 23, in main
    data_ingestion.to_vector_database(pages_and_chunks_over_min_token_len)
  File "c:\users\shaik\documents\programing\ml\rag\src\RAG\components\data_ingestion.py", line 137, in to_vector_database
    index.upsert(
  File "C:\Users\shaik\Documents\Programing\TFOD\tfod\Lib\site-packages\pinecone\utils\error_handling.py", line 10, in inner_func
    return func(*args, **kwargs)
           ^^^^^^^^^^^^^^^^^^^^^
  File "C:\Users\shaik\Documents\Programing\TFOD\tfod\Lib\site-packages\pinecone\data\index.py", line 168, in upsert
    return self._upsert_batch(vectors, namespace, _check_type, **kwargs)
           ^^^^^^^^^^^^^^^^^^^^^^^^^^^^^^^^^^^^^^^^^^^^^^^^^^^^^^^^^^^^^
  File "C:\Users\shaik\Documents\Programing\TFOD\tfod\Lib\site-packages\pinecone\data\index.py", line 189, in _upsert_batch
    return self._vector_api.upsert(
           ^^^^^^^^^^^^^^^^^^^^^^^^
  File "C:\Users\shaik\Documents\Programing\TFOD\tfod\Lib\site-packages\pinecone\core\client\api_client.py", line 772, in __call__
    return self.callable(self, *args, **kwargs)
           ^^^^^^^^^^^^^^^^^^^^^^^^^^^^^^^^^^^^
  File "C:\Users\shaik\Documents\Programing\TFOD\tfod\Lib\site-packages\pinecone\core\client\api\data_plane_api.py", line 1084, in __upsert
    return self.call_with_http_info(**kwargs)
           ^^^^^^^^^^^^^^^^^^^^^^^^^^^^^^^^^^
  File "C:\Users\shaik\Documents\Programing\TFOD\tfod\Lib\site-packages\pinecone\core\client\api_client.py", line 834, in call_with_http_info
    return self.api_client.call_api(
           ^^^^^^^^^^^^^^^^^^^^^^^^^
  File "C:\Users\shaik\Documents\Programing\TFOD\tfod\Lib\site-packages\pinecone\core\client\api_client.py", line 409, in call_api
    return self.__call_api(resource_path, method,
           ^^^^^^^^^^^^^^^^^^^^^^^^^^^^^^^^^^^^^^
  File "C:\Users\shaik\Documents\Programing\TFOD\tfod\Lib\site-packages\pinecone\core\client\api_client.py", line 203, in __call_api
    raise e
  File "C:\Users\shaik\Documents\Programing\TFOD\tfod\Lib\site-packages\pinecone\core\client\api_client.py", line 196, in __call_api
    response_data = self.request(
                    ^^^^^^^^^^^^^
  File "C:\Users\shaik\Documents\Programing\TFOD\tfod\Lib\site-packages\pinecone\core\client\api_client.py", line 455, in request
    return self.rest_client.POST(url,
           ^^^^^^^^^^^^^^^^^^^^^^^^^^
  File "C:\Users\shaik\Documents\Programing\TFOD\tfod\Lib\site-packages\pinecone\core\client\rest.py", line 302, in POST
    return self.request("POST", url,
           ^^^^^^^^^^^^^^^^^^^^^^^^^
  File "C:\Users\shaik\Documents\Programing\TFOD\tfod\Lib\site-packages\pinecone\core\client\rest.py", line 261, in request
    raise PineconeApiException(http_resp=r)
pinecone.core.client.exceptions.PineconeApiException: (400)
Reason: Bad Request
HTTP response headers: HTTPHeaderDict({'Date': 'Mon, 03 Jun 2024 10:12:51 GMT', 'Content-Type': 'application/json', 'Content-Length': '118', 'Connection': 'keep-alive', 'x-pinecone-request-latency-ms': '39446', 'x-pinecone-request-id': '6976461903471582505', 'x-envoy-upstream-service-time': '0', 'server': 'envoy'})
HTTP response body: {"code":11,"message":"Error, message length too large: found 6452785 bytes, the limit is: 4194304 bytes","details":[]}

